INFO 2025-02-04 01:10:26,016 autoreload 35800 135304547152000 Watching for file changes with StatReloader
INFO 2025-02-04 01:10:33,468 autoreload 35800 135304547152000 /home/Agile/code/Stack/vristo/settings.py changed, reloading.
INFO 2025-02-04 01:10:33,849 autoreload 35869 135341850783872 Watching for file changes with StatReloader
INFO 2025-02-04 01:10:46,453 autoreload 35976 139978924753024 Watching for file changes with StatReloader
ERROR 2025-02-04 01:10:51,747 views 35976 139978753443520 IP Analysis error for 8.8.8.8: You cannot call this from an async context - use a thread or sync_to_async.
Traceback (most recent call last):
  File "/home/Agile/code/Stack/main/views.py", line 785, in ip_analysis
    async with IPAnalysisService(request.user) as service:
  File "/home/Agile/code/Stack/main/services/ip_analysis.py", line 56, in __aenter__
    await self._load_api_keys()
  File "/home/Agile/code/Stack/main/services/ip_analysis.py", line 68, in _load_api_keys
    api_keys = APIKey.objects.filter(user=self.user, platform__in=platforms)
               ^^^^^^^^^^^^^^^^^^^^^^^^^^^^^^^^^^^^^^^^^^^^^^^^^^^^^^^^^^^^^
  File "/home/Agile/code/Stack/venv/lib/python3.12/site-packages/django/db/models/manager.py", line 87, in manager_method
    return getattr(self.get_queryset(), name)(*args, **kwargs)
           ^^^^^^^^^^^^^^^^^^^^^^^^^^^^^^^^^^^^^^^^^^^^^^^^^^^
  File "/home/Agile/code/Stack/venv/lib/python3.12/site-packages/django/db/models/query.py", line 1476, in filter
    return self._filter_or_exclude(False, args, kwargs)
           ^^^^^^^^^^^^^^^^^^^^^^^^^^^^^^^^^^^^^^^^^^^^
  File "/home/Agile/code/Stack/venv/lib/python3.12/site-packages/django/db/models/query.py", line 1494, in _filter_or_exclude
    clone._filter_or_exclude_inplace(negate, args, kwargs)
  File "/home/Agile/code/Stack/venv/lib/python3.12/site-packages/django/db/models/query.py", line 1501, in _filter_or_exclude_inplace
    self._query.add_q(Q(*args, **kwargs))
  File "/home/Agile/code/Stack/venv/lib/python3.12/site-packages/django/db/models/sql/query.py", line 1609, in add_q
    clause, _ = self._add_q(q_object, self.used_aliases)
                ^^^^^^^^^^^^^^^^^^^^^^^^^^^^^^^^^^^^^^^^
  File "/home/Agile/code/Stack/venv/lib/python3.12/site-packages/django/db/models/sql/query.py", line 1641, in _add_q
    child_clause, needed_inner = self.build_filter(
                                 ^^^^^^^^^^^^^^^^^^
  File "/home/Agile/code/Stack/venv/lib/python3.12/site-packages/django/db/models/sql/query.py", line 1500, in build_filter
    value = self.resolve_lookup_value(value, can_reuse, allow_joins, summarize)
            ^^^^^^^^^^^^^^^^^^^^^^^^^^^^^^^^^^^^^^^^^^^^^^^^^^^^^^^^^^^^^^^^^^^
  File "/home/Agile/code/Stack/venv/lib/python3.12/site-packages/django/db/models/sql/query.py", line 1269, in resolve_lookup_value
    if hasattr(value, "resolve_expression"):
       ^^^^^^^^^^^^^^^^^^^^^^^^^^^^^^^^^^^^
  File "/home/Agile/code/Stack/venv/lib/python3.12/site-packages/django/utils/functional.py", line 251, in inner
    self._setup()
  File "/home/Agile/code/Stack/venv/lib/python3.12/site-packages/django/utils/functional.py", line 404, in _setup
    self._wrapped = self._setupfunc()
                    ^^^^^^^^^^^^^^^^^
  File "/home/Agile/code/Stack/venv/lib/python3.12/site-packages/django/contrib/auth/middleware.py", line 37, in <lambda>
    request.user = SimpleLazyObject(lambda: get_user(request))
                                            ^^^^^^^^^^^^^^^^^
  File "/home/Agile/code/Stack/venv/lib/python3.12/site-packages/django/contrib/auth/middleware.py", line 17, in get_user
    request._cached_user = auth.get_user(request)
                           ^^^^^^^^^^^^^^^^^^^^^^
  File "/home/Agile/code/Stack/venv/lib/python3.12/site-packages/django/contrib/auth/__init__.py", line 216, in get_user
    user = backend.get_user(user_id)
           ^^^^^^^^^^^^^^^^^^^^^^^^^
  File "/home/Agile/code/Stack/venv/lib/python3.12/site-packages/django/contrib/auth/backends.py", line 157, in get_user
    user = UserModel._default_manager.get(pk=user_id)
           ^^^^^^^^^^^^^^^^^^^^^^^^^^^^^^^^^^^^^^^^^^
  File "/home/Agile/code/Stack/venv/lib/python3.12/site-packages/django/db/models/manager.py", line 87, in manager_method
    return getattr(self.get_queryset(), name)(*args, **kwargs)
           ^^^^^^^^^^^^^^^^^^^^^^^^^^^^^^^^^^^^^^^^^^^^^^^^^^^
  File "/home/Agile/code/Stack/venv/lib/python3.12/site-packages/django/db/models/query.py", line 645, in get
    num = len(clone)
          ^^^^^^^^^^
  File "/home/Agile/code/Stack/venv/lib/python3.12/site-packages/django/db/models/query.py", line 382, in __len__
    self._fetch_all()
  File "/home/Agile/code/Stack/venv/lib/python3.12/site-packages/django/db/models/query.py", line 1928, in _fetch_all
    self._result_cache = list(self._iterable_class(self))
                         ^^^^^^^^^^^^^^^^^^^^^^^^^^^^^^^^
  File "/home/Agile/code/Stack/venv/lib/python3.12/site-packages/django/db/models/query.py", line 91, in __iter__
    results = compiler.execute_sql(
              ^^^^^^^^^^^^^^^^^^^^^
  File "/home/Agile/code/Stack/venv/lib/python3.12/site-packages/django/db/models/sql/compiler.py", line 1572, in execute_sql
    cursor = self.connection.cursor()
             ^^^^^^^^^^^^^^^^^^^^^^^^
  File "/home/Agile/code/Stack/venv/lib/python3.12/site-packages/django/utils/asyncio.py", line 24, in inner
    raise SynchronousOnlyOperation(message)
django.core.exceptions.SynchronousOnlyOperation: You cannot call this from an async context - use a thread or sync_to_async.
ERROR 2025-02-04 01:10:51,750 base_events 35976 139978753443520 Unclosed client session
client_session: <aiohttp.client.ClientSession object at 0x7f4f5e8c6de0>
ERROR 2025-02-04 01:11:04,142 views 35976 139978835232448 IP Analysis error for 8.8.8.8: You cannot call this from an async context - use a thread or sync_to_async.
Traceback (most recent call last):
  File "/home/Agile/code/Stack/main/views.py", line 785, in ip_analysis
    async with IPAnalysisService(request.user) as service:
  File "/home/Agile/code/Stack/main/services/ip_analysis.py", line 56, in __aenter__
    await self._load_api_keys()
  File "/home/Agile/code/Stack/main/services/ip_analysis.py", line 68, in _load_api_keys
    api_keys = APIKey.objects.filter(user=self.user, platform__in=platforms)
               ^^^^^^^^^^^^^^^^^^^^^^^^^^^^^^^^^^^^^^^^^^^^^^^^^^^^^^^^^^^^^
  File "/home/Agile/code/Stack/venv/lib/python3.12/site-packages/django/db/models/manager.py", line 87, in manager_method
    return getattr(self.get_queryset(), name)(*args, **kwargs)
           ^^^^^^^^^^^^^^^^^^^^^^^^^^^^^^^^^^^^^^^^^^^^^^^^^^^
  File "/home/Agile/code/Stack/venv/lib/python3.12/site-packages/django/db/models/query.py", line 1476, in filter
    return self._filter_or_exclude(False, args, kwargs)
           ^^^^^^^^^^^^^^^^^^^^^^^^^^^^^^^^^^^^^^^^^^^^
  File "/home/Agile/code/Stack/venv/lib/python3.12/site-packages/django/db/models/query.py", line 1494, in _filter_or_exclude
    clone._filter_or_exclude_inplace(negate, args, kwargs)
  File "/home/Agile/code/Stack/venv/lib/python3.12/site-packages/django/db/models/query.py", line 1501, in _filter_or_exclude_inplace
    self._query.add_q(Q(*args, **kwargs))
  File "/home/Agile/code/Stack/venv/lib/python3.12/site-packages/django/db/models/sql/query.py", line 1609, in add_q
    clause, _ = self._add_q(q_object, self.used_aliases)
                ^^^^^^^^^^^^^^^^^^^^^^^^^^^^^^^^^^^^^^^^
  File "/home/Agile/code/Stack/venv/lib/python3.12/site-packages/django/db/models/sql/query.py", line 1641, in _add_q
    child_clause, needed_inner = self.build_filter(
                                 ^^^^^^^^^^^^^^^^^^
  File "/home/Agile/code/Stack/venv/lib/python3.12/site-packages/django/db/models/sql/query.py", line 1500, in build_filter
    value = self.resolve_lookup_value(value, can_reuse, allow_joins, summarize)
            ^^^^^^^^^^^^^^^^^^^^^^^^^^^^^^^^^^^^^^^^^^^^^^^^^^^^^^^^^^^^^^^^^^^
  File "/home/Agile/code/Stack/venv/lib/python3.12/site-packages/django/db/models/sql/query.py", line 1269, in resolve_lookup_value
    if hasattr(value, "resolve_expression"):
       ^^^^^^^^^^^^^^^^^^^^^^^^^^^^^^^^^^^^
  File "/home/Agile/code/Stack/venv/lib/python3.12/site-packages/django/utils/functional.py", line 251, in inner
    self._setup()
  File "/home/Agile/code/Stack/venv/lib/python3.12/site-packages/django/utils/functional.py", line 404, in _setup
    self._wrapped = self._setupfunc()
                    ^^^^^^^^^^^^^^^^^
  File "/home/Agile/code/Stack/venv/lib/python3.12/site-packages/django/contrib/auth/middleware.py", line 37, in <lambda>
    request.user = SimpleLazyObject(lambda: get_user(request))
                                            ^^^^^^^^^^^^^^^^^
  File "/home/Agile/code/Stack/venv/lib/python3.12/site-packages/django/contrib/auth/middleware.py", line 17, in get_user
    request._cached_user = auth.get_user(request)
                           ^^^^^^^^^^^^^^^^^^^^^^
  File "/home/Agile/code/Stack/venv/lib/python3.12/site-packages/django/contrib/auth/__init__.py", line 216, in get_user
    user = backend.get_user(user_id)
           ^^^^^^^^^^^^^^^^^^^^^^^^^
  File "/home/Agile/code/Stack/venv/lib/python3.12/site-packages/django/contrib/auth/backends.py", line 157, in get_user
    user = UserModel._default_manager.get(pk=user_id)
           ^^^^^^^^^^^^^^^^^^^^^^^^^^^^^^^^^^^^^^^^^^
  File "/home/Agile/code/Stack/venv/lib/python3.12/site-packages/django/db/models/manager.py", line 87, in manager_method
    return getattr(self.get_queryset(), name)(*args, **kwargs)
           ^^^^^^^^^^^^^^^^^^^^^^^^^^^^^^^^^^^^^^^^^^^^^^^^^^^
  File "/home/Agile/code/Stack/venv/lib/python3.12/site-packages/django/db/models/query.py", line 645, in get
    num = len(clone)
          ^^^^^^^^^^
  File "/home/Agile/code/Stack/venv/lib/python3.12/site-packages/django/db/models/query.py", line 382, in __len__
    self._fetch_all()
  File "/home/Agile/code/Stack/venv/lib/python3.12/site-packages/django/db/models/query.py", line 1928, in _fetch_all
    self._result_cache = list(self._iterable_class(self))
                         ^^^^^^^^^^^^^^^^^^^^^^^^^^^^^^^^
  File "/home/Agile/code/Stack/venv/lib/python3.12/site-packages/django/db/models/query.py", line 91, in __iter__
    results = compiler.execute_sql(
              ^^^^^^^^^^^^^^^^^^^^^
  File "/home/Agile/code/Stack/venv/lib/python3.12/site-packages/django/db/models/sql/compiler.py", line 1572, in execute_sql
    cursor = self.connection.cursor()
             ^^^^^^^^^^^^^^^^^^^^^^^^
  File "/home/Agile/code/Stack/venv/lib/python3.12/site-packages/django/utils/asyncio.py", line 24, in inner
    raise SynchronousOnlyOperation(message)
django.core.exceptions.SynchronousOnlyOperation: You cannot call this from an async context - use a thread or sync_to_async.
ERROR 2025-02-04 01:11:04,144 base_events 35976 139978835232448 Unclosed client session
client_session: <aiohttp.client.ClientSession object at 0x7f4f5e2b2c60>
INFO 2025-02-04 01:11:54,559 autoreload 35976 139978924753024 /home/Agile/code/Stack/main/views.py changed, reloading.
INFO 2025-02-04 01:11:55,017 autoreload 36312 126865143689344 Watching for file changes with StatReloader
INFO 2025-02-04 01:12:17,786 autoreload 36312 126865143689344 /home/Agile/code/Stack/main/services/ip_analysis.py changed, reloading.
INFO 2025-02-04 01:12:18,192 autoreload 36427 127412474253440 Watching for file changes with StatReloader
INFO 2025-02-04 01:13:01,251 autoreload 36427 127412474253440 /home/Agile/code/Stack/main/views.py changed, reloading.
INFO 2025-02-04 01:13:01,833 autoreload 36645 127493650063488 Watching for file changes with StatReloader
ERROR 2025-02-04 01:13:43,097 views 36645 127493581309632 Unexpected error in ip_analysis view: layouts/base.html
Traceback (most recent call last):
  File "/home/Agile/code/Stack/venv/lib/python3.12/site-packages/django/template/backends/django.py", line 107, in render
    return self.template.render(context)
           ^^^^^^^^^^^^^^^^^^^^^^^^^^^^^
  File "/home/Agile/code/Stack/venv/lib/python3.12/site-packages/django/template/base.py", line 171, in render
    return self._render(context)
           ^^^^^^^^^^^^^^^^^^^^^
  File "/home/Agile/code/Stack/venv/lib/python3.12/site-packages/django/template/base.py", line 163, in _render
    return self.nodelist.render(context)
           ^^^^^^^^^^^^^^^^^^^^^^^^^^^^^
  File "/home/Agile/code/Stack/venv/lib/python3.12/site-packages/django/template/base.py", line 1008, in render
    return SafeString("".join([node.render_annotated(context) for node in self]))
                               ^^^^^^^^^^^^^^^^^^^^^^^^^^^^^^
  File "/home/Agile/code/Stack/venv/lib/python3.12/site-packages/django/template/base.py", line 969, in render_annotated
    return self.render(context)
           ^^^^^^^^^^^^^^^^^^^^
  File "/home/Agile/code/Stack/venv/lib/python3.12/site-packages/django/template/loader_tags.py", line 134, in render
    compiled_parent = self.get_parent(context)
                      ^^^^^^^^^^^^^^^^^^^^^^^^
  File "/home/Agile/code/Stack/venv/lib/python3.12/site-packages/django/template/loader_tags.py", line 131, in get_parent
    return self.find_template(parent, context)
           ^^^^^^^^^^^^^^^^^^^^^^^^^^^^^^^^^^^
  File "/home/Agile/code/Stack/venv/lib/python3.12/site-packages/django/template/loader_tags.py", line 109, in find_template
    template, origin = context.template.engine.find_template(
                       ^^^^^^^^^^^^^^^^^^^^^^^^^^^^^^^^^^^^^^
  File "/home/Agile/code/Stack/venv/lib/python3.12/site-packages/django/template/engine.py", line 163, in find_template
    raise TemplateDoesNotExist(name, tried=tried)
django.template.exceptions.TemplateDoesNotExist: layouts/base.html

The above exception was the direct cause of the following exception:

Traceback (most recent call last):
  File "/home/Agile/code/Stack/main/views.py", line 846, in ip_analysis
    return render(request, 'threat/ip_analysis.html', {})
           ^^^^^^^^^^^^^^^^^^^^^^^^^^^^^^^^^^^^^^^^^^^^^^
  File "/home/Agile/code/Stack/venv/lib/python3.12/site-packages/django/shortcuts.py", line 25, in render
    content = loader.render_to_string(template_name, context, request, using=using)
              ^^^^^^^^^^^^^^^^^^^^^^^^^^^^^^^^^^^^^^^^^^^^^^^^^^^^^^^^^^^^^^^^^^^^^
  File "/home/Agile/code/Stack/venv/lib/python3.12/site-packages/django/template/loader.py", line 62, in render_to_string
    return template.render(context, request)
           ^^^^^^^^^^^^^^^^^^^^^^^^^^^^^^^^^
  File "/home/Agile/code/Stack/venv/lib/python3.12/site-packages/django/template/backends/django.py", line 109, in render
    reraise(exc, self.backend)
  File "/home/Agile/code/Stack/venv/lib/python3.12/site-packages/django/template/backends/django.py", line 130, in reraise
    raise new from exc
django.template.exceptions.TemplateDoesNotExist: layouts/base.html
ERROR 2025-02-04 01:13:43,152 log 36645 127493581309632 Internal Server Error: /threat/ip-analysis/
Traceback (most recent call last):
  File "/home/Agile/code/Stack/venv/lib/python3.12/site-packages/django/template/backends/django.py", line 107, in render
    return self.template.render(context)
           ^^^^^^^^^^^^^^^^^^^^^^^^^^^^^
  File "/home/Agile/code/Stack/venv/lib/python3.12/site-packages/django/template/base.py", line 171, in render
    return self._render(context)
           ^^^^^^^^^^^^^^^^^^^^^
  File "/home/Agile/code/Stack/venv/lib/python3.12/site-packages/django/template/base.py", line 163, in _render
    return self.nodelist.render(context)
           ^^^^^^^^^^^^^^^^^^^^^^^^^^^^^
  File "/home/Agile/code/Stack/venv/lib/python3.12/site-packages/django/template/base.py", line 1008, in render
    return SafeString("".join([node.render_annotated(context) for node in self]))
                               ^^^^^^^^^^^^^^^^^^^^^^^^^^^^^^
  File "/home/Agile/code/Stack/venv/lib/python3.12/site-packages/django/template/base.py", line 969, in render_annotated
    return self.render(context)
           ^^^^^^^^^^^^^^^^^^^^
  File "/home/Agile/code/Stack/venv/lib/python3.12/site-packages/django/template/loader_tags.py", line 134, in render
    compiled_parent = self.get_parent(context)
                      ^^^^^^^^^^^^^^^^^^^^^^^^
  File "/home/Agile/code/Stack/venv/lib/python3.12/site-packages/django/template/loader_tags.py", line 131, in get_parent
    return self.find_template(parent, context)
           ^^^^^^^^^^^^^^^^^^^^^^^^^^^^^^^^^^^
  File "/home/Agile/code/Stack/venv/lib/python3.12/site-packages/django/template/loader_tags.py", line 109, in find_template
    template, origin = context.template.engine.find_template(
                       ^^^^^^^^^^^^^^^^^^^^^^^^^^^^^^^^^^^^^^
  File "/home/Agile/code/Stack/venv/lib/python3.12/site-packages/django/template/engine.py", line 163, in find_template
    raise TemplateDoesNotExist(name, tried=tried)
django.template.exceptions.TemplateDoesNotExist: layouts/base.html

The above exception was the direct cause of the following exception:

Traceback (most recent call last):
  File "/home/Agile/code/Stack/main/views.py", line 846, in ip_analysis
    return render(request, 'threat/ip_analysis.html', {})
           ^^^^^^^^^^^^^^^^^^^^^^^^^^^^^^^^^^^^^^^^^^^^^^
  File "/home/Agile/code/Stack/venv/lib/python3.12/site-packages/django/shortcuts.py", line 25, in render
    content = loader.render_to_string(template_name, context, request, using=using)
              ^^^^^^^^^^^^^^^^^^^^^^^^^^^^^^^^^^^^^^^^^^^^^^^^^^^^^^^^^^^^^^^^^^^^^
  File "/home/Agile/code/Stack/venv/lib/python3.12/site-packages/django/template/loader.py", line 62, in render_to_string
    return template.render(context, request)
           ^^^^^^^^^^^^^^^^^^^^^^^^^^^^^^^^^
  File "/home/Agile/code/Stack/venv/lib/python3.12/site-packages/django/template/backends/django.py", line 109, in render
    reraise(exc, self.backend)
  File "/home/Agile/code/Stack/venv/lib/python3.12/site-packages/django/template/backends/django.py", line 130, in reraise
    raise new from exc
django.template.exceptions.TemplateDoesNotExist: layouts/base.html

During handling of the above exception, another exception occurred:

Traceback (most recent call last):
  File "/home/Agile/code/Stack/venv/lib/python3.12/site-packages/django/template/backends/django.py", line 107, in render
    return self.template.render(context)
           ^^^^^^^^^^^^^^^^^^^^^^^^^^^^^
  File "/home/Agile/code/Stack/venv/lib/python3.12/site-packages/django/template/base.py", line 171, in render
    return self._render(context)
           ^^^^^^^^^^^^^^^^^^^^^
  File "/home/Agile/code/Stack/venv/lib/python3.12/site-packages/django/template/base.py", line 163, in _render
    return self.nodelist.render(context)
           ^^^^^^^^^^^^^^^^^^^^^^^^^^^^^
  File "/home/Agile/code/Stack/venv/lib/python3.12/site-packages/django/template/base.py", line 1008, in render
    return SafeString("".join([node.render_annotated(context) for node in self]))
                               ^^^^^^^^^^^^^^^^^^^^^^^^^^^^^^
  File "/home/Agile/code/Stack/venv/lib/python3.12/site-packages/django/template/base.py", line 969, in render_annotated
    return self.render(context)
           ^^^^^^^^^^^^^^^^^^^^
  File "/home/Agile/code/Stack/venv/lib/python3.12/site-packages/django/template/loader_tags.py", line 134, in render
    compiled_parent = self.get_parent(context)
                      ^^^^^^^^^^^^^^^^^^^^^^^^
  File "/home/Agile/code/Stack/venv/lib/python3.12/site-packages/django/template/loader_tags.py", line 131, in get_parent
    return self.find_template(parent, context)
           ^^^^^^^^^^^^^^^^^^^^^^^^^^^^^^^^^^^
  File "/home/Agile/code/Stack/venv/lib/python3.12/site-packages/django/template/loader_tags.py", line 109, in find_template
    template, origin = context.template.engine.find_template(
                       ^^^^^^^^^^^^^^^^^^^^^^^^^^^^^^^^^^^^^^
  File "/home/Agile/code/Stack/venv/lib/python3.12/site-packages/django/template/engine.py", line 163, in find_template
    raise TemplateDoesNotExist(name, tried=tried)
django.template.exceptions.TemplateDoesNotExist: layouts/base.html

The above exception was the direct cause of the following exception:

Traceback (most recent call last):
  File "/home/Agile/code/Stack/venv/lib/python3.12/site-packages/django/core/handlers/exception.py", line 55, in inner
    response = get_response(request)
               ^^^^^^^^^^^^^^^^^^^^^
  File "/home/Agile/code/Stack/venv/lib/python3.12/site-packages/django/core/handlers/base.py", line 197, in _get_response
    response = wrapped_callback(request, *callback_args, **callback_kwargs)
               ^^^^^^^^^^^^^^^^^^^^^^^^^^^^^^^^^^^^^^^^^^^^^^^^^^^^^^^^^^^^
  File "/home/Agile/code/Stack/venv/lib/python3.12/site-packages/django/contrib/auth/decorators.py", line 60, in _view_wrapper
    return view_func(request, *args, **kwargs)
           ^^^^^^^^^^^^^^^^^^^^^^^^^^^^^^^^^^^
  File "/home/Agile/code/Stack/main/views.py", line 784, in wrapped
    return asyncio.run(f(*args, **kwargs))
           ^^^^^^^^^^^^^^^^^^^^^^^^^^^^^^^
  File "/usr/lib/python3.12/asyncio/runners.py", line 194, in run
    return runner.run(main)
           ^^^^^^^^^^^^^^^^
  File "/usr/lib/python3.12/asyncio/runners.py", line 118, in run
    return self._loop.run_until_complete(task)
           ^^^^^^^^^^^^^^^^^^^^^^^^^^^^^^^^^^^
  File "/usr/lib/python3.12/asyncio/base_events.py", line 687, in run_until_complete
    return future.result()
           ^^^^^^^^^^^^^^^
  File "/home/Agile/code/Stack/main/views.py", line 850, in ip_analysis
    return render(request, 'threat/ip_analysis.html', {
           ^^^^^^^^^^^^^^^^^^^^^^^^^^^^^^^^^^^^^^^^^^^^
  File "/home/Agile/code/Stack/venv/lib/python3.12/site-packages/django/shortcuts.py", line 25, in render
    content = loader.render_to_string(template_name, context, request, using=using)
              ^^^^^^^^^^^^^^^^^^^^^^^^^^^^^^^^^^^^^^^^^^^^^^^^^^^^^^^^^^^^^^^^^^^^^
  File "/home/Agile/code/Stack/venv/lib/python3.12/site-packages/django/template/loader.py", line 62, in render_to_string
    return template.render(context, request)
           ^^^^^^^^^^^^^^^^^^^^^^^^^^^^^^^^^
  File "/home/Agile/code/Stack/venv/lib/python3.12/site-packages/django/template/backends/django.py", line 109, in render
    reraise(exc, self.backend)
  File "/home/Agile/code/Stack/venv/lib/python3.12/site-packages/django/template/backends/django.py", line 130, in reraise
    raise new from exc
django.template.exceptions.TemplateDoesNotExist: layouts/base.html
ERROR 2025-02-04 01:13:47,417 views 36645 127493581309632 Unexpected error in ip_analysis view: layouts/base.html
Traceback (most recent call last):
  File "/home/Agile/code/Stack/venv/lib/python3.12/site-packages/django/template/backends/django.py", line 107, in render
    return self.template.render(context)
           ^^^^^^^^^^^^^^^^^^^^^^^^^^^^^
  File "/home/Agile/code/Stack/venv/lib/python3.12/site-packages/django/template/base.py", line 171, in render
    return self._render(context)
           ^^^^^^^^^^^^^^^^^^^^^
  File "/home/Agile/code/Stack/venv/lib/python3.12/site-packages/django/template/base.py", line 163, in _render
    return self.nodelist.render(context)
           ^^^^^^^^^^^^^^^^^^^^^^^^^^^^^
  File "/home/Agile/code/Stack/venv/lib/python3.12/site-packages/django/template/base.py", line 1008, in render
    return SafeString("".join([node.render_annotated(context) for node in self]))
                               ^^^^^^^^^^^^^^^^^^^^^^^^^^^^^^
  File "/home/Agile/code/Stack/venv/lib/python3.12/site-packages/django/template/base.py", line 969, in render_annotated
    return self.render(context)
           ^^^^^^^^^^^^^^^^^^^^
  File "/home/Agile/code/Stack/venv/lib/python3.12/site-packages/django/template/loader_tags.py", line 134, in render
    compiled_parent = self.get_parent(context)
                      ^^^^^^^^^^^^^^^^^^^^^^^^
  File "/home/Agile/code/Stack/venv/lib/python3.12/site-packages/django/template/loader_tags.py", line 131, in get_parent
    return self.find_template(parent, context)
           ^^^^^^^^^^^^^^^^^^^^^^^^^^^^^^^^^^^
  File "/home/Agile/code/Stack/venv/lib/python3.12/site-packages/django/template/loader_tags.py", line 109, in find_template
    template, origin = context.template.engine.find_template(
                       ^^^^^^^^^^^^^^^^^^^^^^^^^^^^^^^^^^^^^^
  File "/home/Agile/code/Stack/venv/lib/python3.12/site-packages/django/template/engine.py", line 163, in find_template
    raise TemplateDoesNotExist(name, tried=tried)
django.template.exceptions.TemplateDoesNotExist: layouts/base.html

The above exception was the direct cause of the following exception:

Traceback (most recent call last):
  File "/home/Agile/code/Stack/main/views.py", line 846, in ip_analysis
    return render(request, 'threat/ip_analysis.html', {})
           ^^^^^^^^^^^^^^^^^^^^^^^^^^^^^^^^^^^^^^^^^^^^^^
  File "/home/Agile/code/Stack/venv/lib/python3.12/site-packages/django/shortcuts.py", line 25, in render
    content = loader.render_to_string(template_name, context, request, using=using)
              ^^^^^^^^^^^^^^^^^^^^^^^^^^^^^^^^^^^^^^^^^^^^^^^^^^^^^^^^^^^^^^^^^^^^^
  File "/home/Agile/code/Stack/venv/lib/python3.12/site-packages/django/template/loader.py", line 62, in render_to_string
    return template.render(context, request)
           ^^^^^^^^^^^^^^^^^^^^^^^^^^^^^^^^^
  File "/home/Agile/code/Stack/venv/lib/python3.12/site-packages/django/template/backends/django.py", line 109, in render
    reraise(exc, self.backend)
  File "/home/Agile/code/Stack/venv/lib/python3.12/site-packages/django/template/backends/django.py", line 130, in reraise
    raise new from exc
django.template.exceptions.TemplateDoesNotExist: layouts/base.html
ERROR 2025-02-04 01:13:47,454 log 36645 127493581309632 Internal Server Error: /threat/ip-analysis/
Traceback (most recent call last):
  File "/home/Agile/code/Stack/venv/lib/python3.12/site-packages/django/template/backends/django.py", line 107, in render
    return self.template.render(context)
           ^^^^^^^^^^^^^^^^^^^^^^^^^^^^^
  File "/home/Agile/code/Stack/venv/lib/python3.12/site-packages/django/template/base.py", line 171, in render
    return self._render(context)
           ^^^^^^^^^^^^^^^^^^^^^
  File "/home/Agile/code/Stack/venv/lib/python3.12/site-packages/django/template/base.py", line 163, in _render
    return self.nodelist.render(context)
           ^^^^^^^^^^^^^^^^^^^^^^^^^^^^^
  File "/home/Agile/code/Stack/venv/lib/python3.12/site-packages/django/template/base.py", line 1008, in render
    return SafeString("".join([node.render_annotated(context) for node in self]))
                               ^^^^^^^^^^^^^^^^^^^^^^^^^^^^^^
  File "/home/Agile/code/Stack/venv/lib/python3.12/site-packages/django/template/base.py", line 969, in render_annotated
    return self.render(context)
           ^^^^^^^^^^^^^^^^^^^^
  File "/home/Agile/code/Stack/venv/lib/python3.12/site-packages/django/template/loader_tags.py", line 134, in render
    compiled_parent = self.get_parent(context)
                      ^^^^^^^^^^^^^^^^^^^^^^^^
  File "/home/Agile/code/Stack/venv/lib/python3.12/site-packages/django/template/loader_tags.py", line 131, in get_parent
    return self.find_template(parent, context)
           ^^^^^^^^^^^^^^^^^^^^^^^^^^^^^^^^^^^
  File "/home/Agile/code/Stack/venv/lib/python3.12/site-packages/django/template/loader_tags.py", line 109, in find_template
    template, origin = context.template.engine.find_template(
                       ^^^^^^^^^^^^^^^^^^^^^^^^^^^^^^^^^^^^^^
  File "/home/Agile/code/Stack/venv/lib/python3.12/site-packages/django/template/engine.py", line 163, in find_template
    raise TemplateDoesNotExist(name, tried=tried)
django.template.exceptions.TemplateDoesNotExist: layouts/base.html

The above exception was the direct cause of the following exception:

Traceback (most recent call last):
  File "/home/Agile/code/Stack/main/views.py", line 846, in ip_analysis
    return render(request, 'threat/ip_analysis.html', {})
           ^^^^^^^^^^^^^^^^^^^^^^^^^^^^^^^^^^^^^^^^^^^^^^
  File "/home/Agile/code/Stack/venv/lib/python3.12/site-packages/django/shortcuts.py", line 25, in render
    content = loader.render_to_string(template_name, context, request, using=using)
              ^^^^^^^^^^^^^^^^^^^^^^^^^^^^^^^^^^^^^^^^^^^^^^^^^^^^^^^^^^^^^^^^^^^^^
  File "/home/Agile/code/Stack/venv/lib/python3.12/site-packages/django/template/loader.py", line 62, in render_to_string
    return template.render(context, request)
           ^^^^^^^^^^^^^^^^^^^^^^^^^^^^^^^^^
  File "/home/Agile/code/Stack/venv/lib/python3.12/site-packages/django/template/backends/django.py", line 109, in render
    reraise(exc, self.backend)
  File "/home/Agile/code/Stack/venv/lib/python3.12/site-packages/django/template/backends/django.py", line 130, in reraise
    raise new from exc
django.template.exceptions.TemplateDoesNotExist: layouts/base.html

During handling of the above exception, another exception occurred:

Traceback (most recent call last):
  File "/home/Agile/code/Stack/venv/lib/python3.12/site-packages/django/template/backends/django.py", line 107, in render
    return self.template.render(context)
           ^^^^^^^^^^^^^^^^^^^^^^^^^^^^^
  File "/home/Agile/code/Stack/venv/lib/python3.12/site-packages/django/template/base.py", line 171, in render
    return self._render(context)
           ^^^^^^^^^^^^^^^^^^^^^
  File "/home/Agile/code/Stack/venv/lib/python3.12/site-packages/django/template/base.py", line 163, in _render
    return self.nodelist.render(context)
           ^^^^^^^^^^^^^^^^^^^^^^^^^^^^^
  File "/home/Agile/code/Stack/venv/lib/python3.12/site-packages/django/template/base.py", line 1008, in render
    return SafeString("".join([node.render_annotated(context) for node in self]))
                               ^^^^^^^^^^^^^^^^^^^^^^^^^^^^^^
  File "/home/Agile/code/Stack/venv/lib/python3.12/site-packages/django/template/base.py", line 969, in render_annotated
    return self.render(context)
           ^^^^^^^^^^^^^^^^^^^^
  File "/home/Agile/code/Stack/venv/lib/python3.12/site-packages/django/template/loader_tags.py", line 134, in render
    compiled_parent = self.get_parent(context)
                      ^^^^^^^^^^^^^^^^^^^^^^^^
  File "/home/Agile/code/Stack/venv/lib/python3.12/site-packages/django/template/loader_tags.py", line 131, in get_parent
    return self.find_template(parent, context)
           ^^^^^^^^^^^^^^^^^^^^^^^^^^^^^^^^^^^
  File "/home/Agile/code/Stack/venv/lib/python3.12/site-packages/django/template/loader_tags.py", line 109, in find_template
    template, origin = context.template.engine.find_template(
                       ^^^^^^^^^^^^^^^^^^^^^^^^^^^^^^^^^^^^^^
  File "/home/Agile/code/Stack/venv/lib/python3.12/site-packages/django/template/engine.py", line 163, in find_template
    raise TemplateDoesNotExist(name, tried=tried)
django.template.exceptions.TemplateDoesNotExist: layouts/base.html

The above exception was the direct cause of the following exception:

Traceback (most recent call last):
  File "/home/Agile/code/Stack/venv/lib/python3.12/site-packages/django/core/handlers/exception.py", line 55, in inner
    response = get_response(request)
               ^^^^^^^^^^^^^^^^^^^^^
  File "/home/Agile/code/Stack/venv/lib/python3.12/site-packages/django/core/handlers/base.py", line 197, in _get_response
    response = wrapped_callback(request, *callback_args, **callback_kwargs)
               ^^^^^^^^^^^^^^^^^^^^^^^^^^^^^^^^^^^^^^^^^^^^^^^^^^^^^^^^^^^^
  File "/home/Agile/code/Stack/venv/lib/python3.12/site-packages/django/contrib/auth/decorators.py", line 60, in _view_wrapper
    return view_func(request, *args, **kwargs)
           ^^^^^^^^^^^^^^^^^^^^^^^^^^^^^^^^^^^
  File "/home/Agile/code/Stack/main/views.py", line 784, in wrapped
    return asyncio.run(f(*args, **kwargs))
           ^^^^^^^^^^^^^^^^^^^^^^^^^^^^^^^
  File "/usr/lib/python3.12/asyncio/runners.py", line 194, in run
    return runner.run(main)
           ^^^^^^^^^^^^^^^^
  File "/usr/lib/python3.12/asyncio/runners.py", line 118, in run
    return self._loop.run_until_complete(task)
           ^^^^^^^^^^^^^^^^^^^^^^^^^^^^^^^^^^^
  File "/usr/lib/python3.12/asyncio/base_events.py", line 687, in run_until_complete
    return future.result()
           ^^^^^^^^^^^^^^^
  File "/home/Agile/code/Stack/main/views.py", line 850, in ip_analysis
    return render(request, 'threat/ip_analysis.html', {
           ^^^^^^^^^^^^^^^^^^^^^^^^^^^^^^^^^^^^^^^^^^^^
  File "/home/Agile/code/Stack/venv/lib/python3.12/site-packages/django/shortcuts.py", line 25, in render
    content = loader.render_to_string(template_name, context, request, using=using)
              ^^^^^^^^^^^^^^^^^^^^^^^^^^^^^^^^^^^^^^^^^^^^^^^^^^^^^^^^^^^^^^^^^^^^^
  File "/home/Agile/code/Stack/venv/lib/python3.12/site-packages/django/template/loader.py", line 62, in render_to_string
    return template.render(context, request)
           ^^^^^^^^^^^^^^^^^^^^^^^^^^^^^^^^^
  File "/home/Agile/code/Stack/venv/lib/python3.12/site-packages/django/template/backends/django.py", line 109, in render
    reraise(exc, self.backend)
  File "/home/Agile/code/Stack/venv/lib/python3.12/site-packages/django/template/backends/django.py", line 130, in reraise
    raise new from exc
django.template.exceptions.TemplateDoesNotExist: layouts/base.html
INFO 2025-02-04 01:14:21,409 autoreload 36645 127493650063488 /home/Agile/code/Stack/vristo/settings.py changed, reloading.
INFO 2025-02-04 01:14:21,823 autoreload 37013 135546519629952 Watching for file changes with StatReloader
INFO 2025-02-04 01:14:33,030 autoreload 37092 140428476694656 Watching for file changes with StatReloader
ERROR 2025-02-04 01:16:12,903 ip_analysis 37092 140428315723456 Error getting API key for virustotal: 'Settings' object has no attribute 'API_KEYS'
Traceback (most recent call last):
  File "/home/Agile/code/Stack/main/services/ip_analysis.py", line 36, in _get_api_key
    encrypted_key = await sync_to_async(lambda: settings.API_KEYS.get(platform))()
                    ^^^^^^^^^^^^^^^^^^^^^^^^^^^^^^^^^^^^^^^^^^^^^^^^^^^^^^^^^^^^^^
  File "/home/Agile/code/Stack/venv/lib/python3.12/site-packages/asgiref/sync.py", line 468, in __call__
    ret = await asyncio.shield(exec_coro)
          ^^^^^^^^^^^^^^^^^^^^^^^^^^^^^^^
  File "/usr/lib/python3.12/concurrent/futures/thread.py", line 58, in run
    result = self.fn(*self.args, **self.kwargs)
             ^^^^^^^^^^^^^^^^^^^^^^^^^^^^^^^^^^
  File "/home/Agile/code/Stack/venv/lib/python3.12/site-packages/asgiref/sync.py", line 522, in thread_handler
    return func(*args, **kwargs)
           ^^^^^^^^^^^^^^^^^^^^^
  File "/home/Agile/code/Stack/main/services/ip_analysis.py", line 36, in <lambda>
    encrypted_key = await sync_to_async(lambda: settings.API_KEYS.get(platform))()
                                                ^^^^^^^^^^^^^^^^^
  File "/home/Agile/code/Stack/venv/lib/python3.12/site-packages/django/conf/__init__.py", line 83, in __getattr__
    val = getattr(_wrapped, name)
          ^^^^^^^^^^^^^^^^^^^^^^^
AttributeError: 'Settings' object has no attribute 'API_KEYS'
ERROR 2025-02-04 01:16:12,910 ip_analysis 37092 140428315723456 Error getting API key for alienvault: 'Settings' object has no attribute 'API_KEYS'
Traceback (most recent call last):
  File "/home/Agile/code/Stack/main/services/ip_analysis.py", line 36, in _get_api_key
    encrypted_key = await sync_to_async(lambda: settings.API_KEYS.get(platform))()
                    ^^^^^^^^^^^^^^^^^^^^^^^^^^^^^^^^^^^^^^^^^^^^^^^^^^^^^^^^^^^^^^
  File "/home/Agile/code/Stack/venv/lib/python3.12/site-packages/asgiref/sync.py", line 468, in __call__
    ret = await asyncio.shield(exec_coro)
          ^^^^^^^^^^^^^^^^^^^^^^^^^^^^^^^
  File "/usr/lib/python3.12/concurrent/futures/thread.py", line 58, in run
    result = self.fn(*self.args, **self.kwargs)
             ^^^^^^^^^^^^^^^^^^^^^^^^^^^^^^^^^^
  File "/home/Agile/code/Stack/venv/lib/python3.12/site-packages/asgiref/sync.py", line 522, in thread_handler
    return func(*args, **kwargs)
           ^^^^^^^^^^^^^^^^^^^^^
  File "/home/Agile/code/Stack/main/services/ip_analysis.py", line 36, in <lambda>
    encrypted_key = await sync_to_async(lambda: settings.API_KEYS.get(platform))()
                                                ^^^^^^^^^^^^^^^^^
  File "/home/Agile/code/Stack/venv/lib/python3.12/site-packages/django/conf/__init__.py", line 83, in __getattr__
    val = getattr(_wrapped, name)
          ^^^^^^^^^^^^^^^^^^^^^^^
AttributeError: 'Settings' object has no attribute 'API_KEYS'
ERROR 2025-02-04 01:16:12,912 ip_analysis 37092 140428315723456 Error getting API key for ibmxforce: 'Settings' object has no attribute 'API_KEYS'
Traceback (most recent call last):
  File "/home/Agile/code/Stack/main/services/ip_analysis.py", line 36, in _get_api_key
    encrypted_key = await sync_to_async(lambda: settings.API_KEYS.get(platform))()
                    ^^^^^^^^^^^^^^^^^^^^^^^^^^^^^^^^^^^^^^^^^^^^^^^^^^^^^^^^^^^^^^
  File "/home/Agile/code/Stack/venv/lib/python3.12/site-packages/asgiref/sync.py", line 468, in __call__
    ret = await asyncio.shield(exec_coro)
          ^^^^^^^^^^^^^^^^^^^^^^^^^^^^^^^
  File "/usr/lib/python3.12/concurrent/futures/thread.py", line 58, in run
    result = self.fn(*self.args, **self.kwargs)
             ^^^^^^^^^^^^^^^^^^^^^^^^^^^^^^^^^^
  File "/home/Agile/code/Stack/venv/lib/python3.12/site-packages/asgiref/sync.py", line 522, in thread_handler
    return func(*args, **kwargs)
           ^^^^^^^^^^^^^^^^^^^^^
  File "/home/Agile/code/Stack/main/services/ip_analysis.py", line 36, in <lambda>
    encrypted_key = await sync_to_async(lambda: settings.API_KEYS.get(platform))()
                                                ^^^^^^^^^^^^^^^^^
  File "/home/Agile/code/Stack/venv/lib/python3.12/site-packages/django/conf/__init__.py", line 83, in __getattr__
    val = getattr(_wrapped, name)
          ^^^^^^^^^^^^^^^^^^^^^^^
AttributeError: 'Settings' object has no attribute 'API_KEYS'
ERROR 2025-02-04 01:16:13,458 base_events 37092 140428476694656 Unclosed client session
client_session: <aiohttp.client.ClientSession object at 0x7fb8096fc260>
INFO 2025-02-04 01:21:01,331 autoreload 38978 139047083962496 Watching for file changes with StatReloader
ERROR 2025-02-04 01:21:56,111 ip_analysis 38978 139046946866880 Error getting API key for virustotal: 'Settings' object has no attribute 'API_KEYS'
Traceback (most recent call last):
  File "/home/Agile/code/Stack/main/services/ip_analysis.py", line 36, in _get_api_key
    encrypted_key = await sync_to_async(lambda: settings.API_KEYS.get(platform))()
                    ^^^^^^^^^^^^^^^^^^^^^^^^^^^^^^^^^^^^^^^^^^^^^^^^^^^^^^^^^^^^^^
  File "/home/Agile/code/Stack/venv/lib/python3.12/site-packages/asgiref/sync.py", line 468, in __call__
    ret = await asyncio.shield(exec_coro)
          ^^^^^^^^^^^^^^^^^^^^^^^^^^^^^^^
  File "/usr/lib/python3.12/concurrent/futures/thread.py", line 58, in run
    result = self.fn(*self.args, **self.kwargs)
             ^^^^^^^^^^^^^^^^^^^^^^^^^^^^^^^^^^
  File "/home/Agile/code/Stack/venv/lib/python3.12/site-packages/asgiref/sync.py", line 522, in thread_handler
    return func(*args, **kwargs)
           ^^^^^^^^^^^^^^^^^^^^^
  File "/home/Agile/code/Stack/main/services/ip_analysis.py", line 36, in <lambda>
    encrypted_key = await sync_to_async(lambda: settings.API_KEYS.get(platform))()
                                                ^^^^^^^^^^^^^^^^^
  File "/home/Agile/code/Stack/venv/lib/python3.12/site-packages/django/conf/__init__.py", line 83, in __getattr__
    val = getattr(_wrapped, name)
          ^^^^^^^^^^^^^^^^^^^^^^^
AttributeError: 'Settings' object has no attribute 'API_KEYS'
ERROR 2025-02-04 01:21:56,114 ip_analysis 38978 139046946866880 Error getting API key for alienvault: 'Settings' object has no attribute 'API_KEYS'
Traceback (most recent call last):
  File "/home/Agile/code/Stack/main/services/ip_analysis.py", line 36, in _get_api_key
    encrypted_key = await sync_to_async(lambda: settings.API_KEYS.get(platform))()
                    ^^^^^^^^^^^^^^^^^^^^^^^^^^^^^^^^^^^^^^^^^^^^^^^^^^^^^^^^^^^^^^
  File "/home/Agile/code/Stack/venv/lib/python3.12/site-packages/asgiref/sync.py", line 468, in __call__
    ret = await asyncio.shield(exec_coro)
          ^^^^^^^^^^^^^^^^^^^^^^^^^^^^^^^
  File "/usr/lib/python3.12/concurrent/futures/thread.py", line 58, in run
    result = self.fn(*self.args, **self.kwargs)
             ^^^^^^^^^^^^^^^^^^^^^^^^^^^^^^^^^^
  File "/home/Agile/code/Stack/venv/lib/python3.12/site-packages/asgiref/sync.py", line 522, in thread_handler
    return func(*args, **kwargs)
           ^^^^^^^^^^^^^^^^^^^^^
  File "/home/Agile/code/Stack/main/services/ip_analysis.py", line 36, in <lambda>
    encrypted_key = await sync_to_async(lambda: settings.API_KEYS.get(platform))()
                                                ^^^^^^^^^^^^^^^^^
  File "/home/Agile/code/Stack/venv/lib/python3.12/site-packages/django/conf/__init__.py", line 83, in __getattr__
    val = getattr(_wrapped, name)
          ^^^^^^^^^^^^^^^^^^^^^^^
AttributeError: 'Settings' object has no attribute 'API_KEYS'
ERROR 2025-02-04 01:21:56,116 ip_analysis 38978 139046946866880 Error getting API key for ibmxforce: 'Settings' object has no attribute 'API_KEYS'
Traceback (most recent call last):
  File "/home/Agile/code/Stack/main/services/ip_analysis.py", line 36, in _get_api_key
    encrypted_key = await sync_to_async(lambda: settings.API_KEYS.get(platform))()
                    ^^^^^^^^^^^^^^^^^^^^^^^^^^^^^^^^^^^^^^^^^^^^^^^^^^^^^^^^^^^^^^
  File "/home/Agile/code/Stack/venv/lib/python3.12/site-packages/asgiref/sync.py", line 468, in __call__
    ret = await asyncio.shield(exec_coro)
          ^^^^^^^^^^^^^^^^^^^^^^^^^^^^^^^
  File "/usr/lib/python3.12/concurrent/futures/thread.py", line 58, in run
    result = self.fn(*self.args, **self.kwargs)
             ^^^^^^^^^^^^^^^^^^^^^^^^^^^^^^^^^^
  File "/home/Agile/code/Stack/venv/lib/python3.12/site-packages/asgiref/sync.py", line 522, in thread_handler
    return func(*args, **kwargs)
           ^^^^^^^^^^^^^^^^^^^^^
  File "/home/Agile/code/Stack/main/services/ip_analysis.py", line 36, in <lambda>
    encrypted_key = await sync_to_async(lambda: settings.API_KEYS.get(platform))()
                                                ^^^^^^^^^^^^^^^^^
  File "/home/Agile/code/Stack/venv/lib/python3.12/site-packages/django/conf/__init__.py", line 83, in __getattr__
    val = getattr(_wrapped, name)
          ^^^^^^^^^^^^^^^^^^^^^^^
AttributeError: 'Settings' object has no attribute 'API_KEYS'
INFO 2025-02-04 01:22:35,677 autoreload 38978 139047083962496 /home/Agile/code/Stack/vristo/settings.py changed, reloading.
ERROR 2025-02-04 01:22:35,706 base_events 38978 139047083962496 Unclosed client session
client_session: <aiohttp.client.ClientSession object at 0x7e76682bac30>
INFO 2025-02-04 01:22:36,080 autoreload 39416 124954850791552 Watching for file changes with StatReloader
INFO 2025-02-04 01:22:53,669 autoreload 39416 124954850791552 /home/Agile/code/Stack/main/services/ip_analysis.py changed, reloading.
INFO 2025-02-04 01:22:54,178 autoreload 39516 123143546282112 Watching for file changes with StatReloader
INFO 2025-02-04 01:23:06,054 views 39516 123143477790400 Returning cached result for IP: 93.127.57.211
INFO 2025-02-04 01:25:26,035 autoreload 39516 123143546282112 /home/Agile/code/Stack/main/models.py changed, reloading.
INFO 2025-02-04 01:25:26,417 autoreload 40129 125053771362432 Watching for file changes with StatReloader
INFO 2025-02-04 01:25:52,095 autoreload 40129 125053771362432 /home/Agile/code/Stack/main/services/ip_analysis.py changed, reloading.
INFO 2025-02-04 01:25:52,598 autoreload 40268 124708680134784 Watching for file changes with StatReloader
INFO 2025-02-04 01:28:25,229 autoreload 40919 133089711128704 Watching for file changes with StatReloader
ERROR 2025-02-04 01:28:33,732 ip_analysis 40919 133089642677952 Error getting API key for virustotal: 'APIKey' object has no attribute 'get_decrypted_key'
Traceback (most recent call last):
  File "/home/Agile/code/Stack/main/services/ip_analysis.py", line 44, in _get_api_key
    decrypted_key = await sync_to_async(api_key.get_decrypted_key)()
                                        ^^^^^^^^^^^^^^^^^^^^^^^^^
AttributeError: 'APIKey' object has no attribute 'get_decrypted_key'. Did you mean: 'get_decrypted_api_key'?
ERROR 2025-02-04 01:28:33,737 ip_analysis 40919 133089642677952 Error getting API key for alienvault: 'APIKey' object has no attribute 'get_decrypted_key'
Traceback (most recent call last):
  File "/home/Agile/code/Stack/main/services/ip_analysis.py", line 44, in _get_api_key
    decrypted_key = await sync_to_async(api_key.get_decrypted_key)()
                                        ^^^^^^^^^^^^^^^^^^^^^^^^^
AttributeError: 'APIKey' object has no attribute 'get_decrypted_key'. Did you mean: 'get_decrypted_api_key'?
WARNING 2025-02-04 01:28:33,741 ip_analysis 40919 133089642677952 No API key configured for ibmxforce
INFO 2025-02-04 01:29:36,333 autoreload 40919 133089711128704 /home/Agile/code/Stack/main/services/ip_analysis.py changed, reloading.
INFO 2025-02-04 01:29:36,966 autoreload 41219 140228063031424 Watching for file changes with StatReloader
WARNING 2025-02-04 01:29:45,149 ip_analysis 41219 140227926558400 No API key configured for ibmxforce
INFO 2025-02-04 01:30:46,088 autoreload 41219 140228063031424 /home/Agile/code/Stack/main/views.py changed, reloading.
INFO 2025-02-04 01:30:46,561 autoreload 41532 139923115016320 Watching for file changes with StatReloader
WARNING 2025-02-04 01:30:55,571 ip_analysis 41532 139922979686080 No API key configured for ibmxforce
WARNING 2025-02-04 01:31:18,022 ip_analysis 41532 139922979686080 No API key configured for ibmxforce
